#VRML_SIM R2021b utf8
WorldInfo {
  coordinateSystem "NUE"
}
Viewpoint {
  orientation 1 0 0 4.71238898038469
  position 0.00010082733925309419 12.497873857215035 1.45345891652605e-06
  follow "robot"
}
TexturedBackground {
}
TexturedBackgroundLight {
}
RectangleArena {
  floorSize 6 6
}
Robot {
  translation -2.5 0.0333498 -2.5
  children [
    GPS {
    }
    Compass {
    }
    DEF GROUP_RB Group {
      children [
        DEF WHEELS_GR Group {
          children [
            DEF WHEEL_1 Transform {
              translation -0.115 0 -0.139
              rotation 0 1 0 0.6999996938995747
              children [
                HingeJoint {
                  jointParameters HingeJointParameters {
                    axis 0 0 1
                  }
                  device [
                    RotationalMotor {
                      name "wheel motor 1"
                      controlPID 10 0 5
                      maxVelocity 100
                      maxTorque 50
                    }
                    PositionSensor {
                      name "position_sensor1"
                      resolution 0.003848528
                    }
                  ]
                  endPoint Solid {
                    translation -2.1022674952721978e-05 -0.00010036692727753009 -4.741542575070755e-06
                    rotation -0.0021114985073503825 -0.000626011164681212 0.9999975748390968 5.895627792741744
                    children [
                      DEF WHEELS_TR1 Transform {
                        rotation 1 0 0 1.57
                        children [
                          DEF WHEELS_SH Shape {
                            appearance DEF COLOR_WHEEL PBRAppearance {
                              baseColor 0 0 0
                              roughness 1
                              metalness 0
                            }
                            geometry DEF SIZE_WHEEL Cylinder {
                              height 0.02
                              radius 0.04
                            }
                          }
                        ]
                      }
                      DEF SW1_1 HingeJoint {
                        jointParameters HingeJointParameters {
                          anchor 0 0.04 0
                        }
                        endPoint Solid {
                          translation 0 0.04 0
                          rotation -7.668291473077865e-09 7.6621881243843e-09 1 1.5699999999999952
                          children [
                            DEF SMALL_WHEEL_TR1 Transform {
                              children [
                                DEF SMALL_WHEEL_SH Shape {
                                  appearance PBRAppearance {
                                    roughness 1
                                    metalness 0
                                  }
                                  geometry Cylinder {
                                    height 0.02
                                    radius 0.005
                                  }
                                }
                              ]
                            }
                          ]
                          boundingObject USE SMALL_WHEEL_TR1
                          physics Physics {
                            mass 0.1
                          }
                        }
                      }
                      DEF SW1_2 HingeJoint {
                        jointParameters HingeJointParameters {
                          axis 1 -1 0
                          anchor 0.02828 0.02828 0
                        }
                        endPoint Solid {
                          translation 0.02828 0.02828 0
                          rotation -3.2600692574511673e-09 7.869410716285397e-09 1 0.7852999999999906
                          children [
                            USE SMALL_WHEEL_SH
                          ]
                          name "solid(1)"
                          boundingObject USE SMALL_WHEEL_SH
                          physics Physics {
                            mass 0.1
                          }
                        }
                      }
                      DEF SW1_3 HingeJoint {
                        jointParameters HingeJointParameters {
                          axis 1 1 0
                          anchor -0.02828 0.02828 0
                        }
                        endPoint Solid {
                          translation -0.02828 0.02828 0
                          rotation -7.57332610309643e-09 -1.8281092690735185e-08 -0.9999999999999999 0.7852999999999859
                          children [
                            Transform {
                              children [
                                USE SMALL_WHEEL_SH
                              ]
                            }
                          ]
                          name "solid(2)"
                          boundingObject USE SMALL_WHEEL_SH
                          physics Physics {
                            mass 0.1
                          }
                        }
                      }
                      DEF SW1_4 HingeJoint {
                        jointParameters HingeJointParameters {
                          axis 0 1 0
                          anchor -0.04 0 0
                        }
                        endPoint Solid {
                          translation -0.04 0 0
                          children [
                            Transform {
                              children [
                                USE SMALL_WHEEL_SH
                              ]
                            }
                          ]
                          name "solid(3)"
                          boundingObject USE SMALL_WHEEL_SH
                          physics Physics {
                            mass 0.1
                          }
                        }
                      }
                      DEF SW1_5 HingeJoint {
                        jointParameters HingeJointParameters {
                          axis 0 1 0
                          anchor 0.04 0 0
                        }
                        endPoint Solid {
                          translation 0.04 0 0
                          children [
                            Transform {
                              children [
                                USE SMALL_WHEEL_SH
                              ]
                            }
                          ]
                          name "solid(4)"
                          boundingObject USE SMALL_WHEEL_SH
                          physics Physics {
                            mass 0.1
                          }
                        }
                      }
                      DEF SW1_6 HingeJoint {
                        jointParameters HingeJointParameters {
                          axis 1 -1 0
                          anchor -0.02828 -0.02828 0
                        }
                        endPoint Solid {
                          translation -0.02828 -0.02828 0
                          rotation -3.260068568345787e-09 7.86941082509154e-09 1 0.7852999999999882
                          children [
                            Transform {
                              children [
                                USE SMALL_WHEEL_SH
                              ]
                            }
                          ]
                          name "solid(5)"
                          boundingObject USE SMALL_WHEEL_SH
                          physics Physics {
                            mass 0.1
                          }
                        }
                      }
                      DEF SW1_7 HingeJoint {
                        jointParameters HingeJointParameters {
                          axis 1 1 0
                          anchor 0.02828 -0.02828 0
                        }
                        endPoint Solid {
                          translation 0.02828 -0.02828 0
                          rotation 6.481271592601126e-10 1.5644988562733262e-09 -0.9999999999999999 0.785299999999983
                          children [
                            Transform {
                              children [
                                USE SMALL_WHEEL_SH
                              ]
                            }
                          ]
                          name "solid(6)"
                          boundingObject USE SMALL_WHEEL_SH
                          physics Physics {
                            mass 0.1
                          }
                        }
                      }
                      DEF SW1_8 HingeJoint {
                        jointParameters HingeJointParameters {
                          anchor 0 -0.04 0
                        }
                        endPoint Solid {
                          translation 0 -0.04 0
                          rotation 6.528325685862076e-10 -6.523100692483032e-10 1 1.5699999999999958
                          children [
                            Transform {
                              children [
                                USE SMALL_WHEEL_SH
                              ]
                            }
                          ]
                          name "solid(7)"
                          boundingObject USE SMALL_WHEEL_SH
                          physics Physics {
                            mass 0.1
                          }
                        }
                      }
                    ]
                    name "solid(4)"
                    boundingObject USE WHEELS_TR1
                    physics Physics {
                      mass 0.1
                    }
                  }
                }
              ]
            }
            DEF WHEEL_2 Transform {
              translation -0.115 0 0.139
              rotation 0 1 0 -0.7
              children [
                HingeJoint {
                  jointParameters HingeJointParameters {
                    axis 0 0 1
                  }
                  device [
                    RotationalMotor {
                      name "wheel motor 2"
                      controlPID 10 0 5
                      maxVelocity 100
                      maxTorque 50
                    }
                    PositionSensor {
                      name "position_sensor2"
                      resolution 0.003848528
                    }
                  ]
                  endPoint Solid {
                    translation 7.487471054116356e-05 -2.6036251455752345e-06 8.505712828676925e-06
                    rotation 0.003779544543536751 -0.0036290150932076965 0.999986272552027 6.074605488200025
                    children [
                      DEF WHEEL_TR2 Transform {
                        rotation 1 0 0 1.57
                        children [
                          USE WHEELS_SH
                        ]
                      }
                      DEF SW2_1 HingeJoint {
                        jointParameters HingeJointParameters {
                          anchor 0 0.04 0
                        }
                        endPoint Solid {
                          translation 0 0.04 0
                          rotation 1.2368582258280167e-08 -1.2358737312090129e-08 0.9999999999999999 1.569999999999995
                          children [
                            DEF SMALL_WHEEL_TR2 Transform {
                              children [
                                USE SMALL_WHEEL_SH
                              ]
                            }
                          ]
                          boundingObject USE SMALL_WHEEL_TR2
                          physics Physics {
                            mass 0.1
                          }
                        }
                      }
                      DEF SW2_2 HingeJoint {
                        jointParameters HingeJointParameters {
                          axis 1 -1 0
                          anchor 0.02828 0.02828 0
                        }
                        endPoint Solid {
                          translation 0.02828 0.02828 0
                          rotation -7.9502575038231e-10 1.9190928694601464e-09 1 0.7852999999999877
                          children [
                            Transform {
                              children [
                                USE SMALL_WHEEL_SH
                              ]
                            }
                          ]
                          name "solid(1)"
                          boundingObject USE SMALL_WHEEL_SH
                          physics Physics {
                          }
                        }
                      }
                      DEF SW2_3 HingeJoint {
                        jointParameters HingeJointParameters {
                          axis 1 1 0
                          anchor -0.02828 0.02828 0
                        }
                        endPoint Solid {
                          translation -0.02828 0.02828 0
                          rotation -5.9278461562715105e-09 -1.430909933208715e-08 -1 0.785299999999979
                          children [
                            Transform {
                              children [
                                USE SMALL_WHEEL_SH
                              ]
                            }
                          ]
                          name "solid(2)"
                          boundingObject USE SMALL_WHEEL_SH
                          physics Physics {
                            mass 0.1
                          }
                        }
                      }
                      DEF SW2_4 HingeJoint {
                        jointParameters HingeJointParameters {
                          axis 0 1 0
                          anchor -0.04 0 0
                        }
                        endPoint Solid {
                          translation -0.04 0 0
                          children [
                            Transform {
                              children [
                                USE SMALL_WHEEL_SH
                              ]
                            }
                          ]
                          name "solid(3)"
                          boundingObject USE SMALL_WHEEL_SH
                          physics Physics {
                            mass 0.1
                          }
                        }
                      }
                      DEF SW2_5 HingeJoint {
                        jointParameters HingeJointParameters {
                          axis 0 1 0
                          anchor 0.04 0 0
                        }
                        endPoint Solid {
                          translation 0.04 0 0
                          rotation 0 1 0 1.57000000000062
                          children [
                            Transform {
                              children [
                                USE SMALL_WHEEL_SH
                              ]
                            }
                          ]
                          name "solid(4)"
                          boundingObject USE SMALL_WHEEL_SH
                          physics Physics {
                            mass 0.1
                          }
                        }
                      }
                      DEF SW2_6 HingeJoint {
                        jointParameters HingeJointParameters {
                          axis 1 -1 0
                          anchor -0.02828 -0.02828 0
                        }
                        endPoint Solid {
                          translation -0.02828 -0.02828 0
                          rotation -7.950261493380611e-10 1.9190921803547493e-09 1 0.78529999999999
                          children [
                            Transform {
                              children [
                                USE SMALL_WHEEL_SH
                              ]
                            }
                          ]
                          name "solid(5)"
                          boundingObject USE SMALL_WHEEL_SH
                          physics Physics {
                            mass 0.1
                          }
                        }
                      }
                      DEF SW2_7 HingeJoint {
                        jointParameters HingeJointParameters {
                          axis 1 1 0
                          anchor 0.02828 -0.02828 0
                        }
                        endPoint Solid {
                          translation 0.02828 -0.02828 0
                          rotation -5.927844886866824e-09 -1.4309097228502227e-08 -0.9999999999999999 0.7852999999999819
                          children [
                            Transform {
                              children [
                                USE SMALL_WHEEL_SH
                              ]
                            }
                          ]
                          name "solid(6)"
                          boundingObject USE SMALL_WHEEL_SH
                          physics Physics {
                            mass 0.1
                          }
                        }
                      }
                      DEF SW2_8 HingeJoint {
                        jointParameters HingeJointParameters {
                          anchor 0 -0.04 0
                        }
                        endPoint Solid {
                          translation 0 -0.04 0
                          rotation -5.497512949540494e-16 0 1 1.5699999999999974
                          children [
                            Transform {
                              children [
                                USE SMALL_WHEEL_SH
                              ]
                            }
                          ]
                          name "solid(7)"
                          boundingObject USE SMALL_WHEEL_SH
                          physics Physics {
                            mass 0.1
                          }
                        }
                      }
                    ]
                    name "solid(2)"
                    boundingObject USE WHEEL_TR2
                    physics Physics {
                      mass 0.1
                    }
                  }
                }
              ]
            }
            DEF WHEEL_3 Transform {
              translation 0.18 0 0
              rotation 0 1 0 1.57
              children [
                HingeJoint {
                  jointParameters HingeJointParameters {
                    axis 0 0 1
                  }
                  device [
                    RotationalMotor {
                      name "wheel motor 3"
                      controlPID 10 0 5
                      maxVelocity 100
                      maxTorque 50
                    }
                    PositionSensor {
                      name "position_sensor3"
                      resolution 0.003848528
                    }
                  ]
                  endPoint Solid {
                    translation -5.080107331449836e-05 0.00043303190987550454 1.170381764481472e-05
                    rotation -2.3587923327299484e-07 6.091967498161333e-06 -0.9999999999814163 0.18654317754715652
                    children [
                      DEF WHEEL_TR3 Transform {
                        rotation 1 0 0 1.57
                        children [
                          USE WHEELS_SH
                        ]
                      }
                      DEF SW3_1 HingeJoint {
                        jointParameters HingeJointParameters {
                          anchor 0 0.04 0
                        }
                        endPoint Solid {
                          translation 0 0.04 0
                          rotation -4.113905644487482e-09 4.110630540415743e-09 1 1.569999999999997
                          children [
                            Transform {
                              children [
                                USE SMALL_WHEEL_SH
                              ]
                            }
                          ]
                          boundingObject USE SMALL_WHEEL_SH
                          physics Physics {
                            mass 0.1
                          }
                        }
                      }
                      DEF SW3_2 HingeJoint {
                        jointParameters HingeJointParameters {
                          axis 1 -1 0
                          anchor 0.02828 0.02828 0
                        }
                        endPoint Solid {
                          translation 0.02828 0.02828 0
                          rotation -2.356686544234385e-09 5.688756289429402e-09 1 0.7852999999999801
                          children [
                            Transform {
                              children [
                                USE SMALL_WHEEL_SH
                              ]
                            }
                          ]
                          name "solid(1)"
                          boundingObject USE SMALL_WHEEL_SH
                          physics Physics {
                            mass 0.1
                          }
                        }
                      }
                      DEF SW3_3 HingeJoint {
                        jointParameters HingeJointParameters {
                          axis 1 1 0
                          anchor -0.02828 0.02828 0
                        }
                        endPoint Solid {
                          translation -0.02828 0.02828 0
                          rotation -3.4573368103106117e-09 -8.345590557316816e-09 -0.9999999999999999 0.7852999999999929
                          children [
                            Transform {
                              children [
                                USE SMALL_WHEEL_SH
                              ]
                            }
                          ]
                          name "solid(2)"
                          boundingObject USE SMALL_WHEEL_SH
                          physics Physics {
                            mass 0.1
                          }
                        }
                      }
                      DEF SW3_4 HingeJoint {
                        jointParameters HingeJointParameters {
                          axis 0 1 0
                          anchor -0.04 0 0
                        }
                        endPoint Solid {
                          translation -0.04 0 0
                          children [
                            Transform {
                              children [
                                USE SMALL_WHEEL_SH
                              ]
                            }
                          ]
                          name "solid(3)"
                          boundingObject USE SMALL_WHEEL_SH
                          physics Physics {
                            mass 0.1
                          }
                        }
                      }
                      DEF SW3_5 HingeJoint {
                        jointParameters HingeJointParameters {
                          axis 0 1 0
                          anchor 0.04 0 0
                        }
                        endPoint Solid {
                          translation 0.04 0 0
                          rotation 0 1 0 1.5699999984434723
                          children [
                            Transform {
                              children [
                                USE SMALL_WHEEL_SH
                              ]
                            }
                          ]
                          name "solid(4)"
                          boundingObject USE SMALL_WHEEL_SH
                          physics Physics {
                            mass 0.1
                          }
                        }
                      }
                      DEF SW3_6 HingeJoint {
                        jointParameters HingeJointParameters {
                          axis 1 -1 0
                          anchor -0.02828 -0.02828 0
                        }
                        endPoint Solid {
                          translation -0.02828 -0.02828 0
                          rotation -2.3566889742375696e-09 5.688758066595845e-09 1 0.7852999999999947
                          children [
                            Transform {
                              children [
                                USE SMALL_WHEEL_SH
                              ]
                            }
                          ]
                          name "solid(5)"
                          boundingObject USE SMALL_WHEEL_SH
                          physics Physics {
                            mass 0.1
                          }
                        }
                      }
                      DEF SW3_7 HingeJoint {
                        jointParameters HingeJointParameters {
                          axis 1 1 0
                          anchor 0.02828 -0.02828 0
                        }
                        endPoint Solid {
                          translation 0.02828 -0.02828 0
                          rotation -3.457335604376193e-09 -8.345588281455632e-09 -1 0.7852999999999882
                          children [
                            Transform {
                              children [
                                USE SMALL_WHEEL_SH
                              ]
                            }
                          ]
                          name "solid(6)"
                          boundingObject USE SMALL_WHEEL_SH
                          physics Physics {
                            mass 0.1
                          }
                        }
                      }
                      DEF SW3_8 HingeJoint {
                        jointParameters HingeJointParameters {
                          anchor 0 -0.04 0
                        }
                        endPoint Solid {
                          translation 0 -0.04 0
                          rotation 1.178038489187249e-16 6.871891186925619e-17 1 1.5699999999999958
                          children [
                            Transform {
                              children [
                                USE SMALL_WHEEL_SH
                              ]
                            }
                          ]
                          name "solid(7)"
                          boundingObject USE SMALL_WHEEL_SH
                          physics Physics {
                            mass 0.1
                          }
                        }
                      }
                    ]
                    name "solid(5)"
                    boundingObject USE WHEEL_TR3
                    physics Physics {
                      mass 0.1
                    }
                  }
                }
              ]
            }
          ]
        }
        DEF BASE_GR Group {
          children [
            DEF BOTTOM_BASE Transform {
              translation 0 0.015 0
              children [
                HingeJoint {
                  jointParameters HingeJointParameters {
                    axis 0 1 0
                  }
                  endPoint Solid {
                    translation -5.5961205946640796e-18 0.1499999999999991 3.851859888774472e-34
                    children [
                      Shape {
                        appearance DEF BASE_COLOR PBRAppearance {
                          baseColor 0.180392 0.203922 0.211765
                          roughness 1
                          metalness 0
                        }
                        geometry DEF BOTTOM_BASE_GM Cylinder {
                          height 0.3
                          radius 0.17
                        }
                      }
                      DEF BASE_TOP Transform {
                        translation 0 0.175 0
                        children [
                          DEF solid Solid {
                            children [
                              Shape {
                                appearance USE BASE_COLOR
                                geometry DEF TOP_BASE Cylinder {
                                  height 0.05
                                  radius 0.1
                                }
                              }
                            ]
                            boundingObject USE TOP_BASE
                            physics Physics {
                            }
                          }
                        ]
                      }
                    ]
                    name "solid(3)"
                    boundingObject USE BOTTOM_BASE_GM
                    physics Physics {
                      mass 40
                    }
                  }
                }
              ]
            }
            Transform {
              translation 0.55 0.715 0.05
              children [
                Shape {
                  geometry Cylinder {
                    height 0.1
                    radius 0.05
                  }
                }
              ]
            }
          ]
        }
        DEF LINKS_GR Group {
          children [
            DEF LINK_1 Transform {
              translation 0 0.525 0
              children [
                HingeJoint {
                  jointParameters HingeJointParameters {
                    axis 0 1 0
                  }
                  device [
                    RotationalMotor {
                      name "rotational motor link 1"
                      maxTorque 100
                    }
                    PositionSensor {
                      name "position sensor link 1"
                    }
                  ]
                  endPoint Solid {
                    translation 0 0.01599999999999987 0
                    rotation 9.026253910977755e-17 -2.931765097506931e-05 0.9999999995702378 4.691192266720667e-06
                    children [
                      Shape {
                        appearance DEF LINKS_COLOR PBRAppearance {
                          baseColor 0 0 0
                          roughness 1
                          metalness 0
                        }
                        geometry DEF LINK_1_GM Cylinder {
                          height 0.35
                          radius 0.05
                        }
                      }
                      DEF LINK_2 Transform {
                        translation 0 0.175 0
                        children [
                          HingeJoint {
                            jointParameters HingeJointParameters {
                              axis 0 0 1
                            }
                            device [
                              RotationalMotor {
                                name "rotational motor link 2"
                                controlPID 50 5 0
                                maxTorque 300
                              }
                              PositionSensor {
                                name "position sensor link 2"
                              }
                            ]
                            endPoint Solid {
                              translation 3.995787345698733e-06 -1.1068431184228767e-07 0.07500040380508285
                              rotation 2.065012250793802e-05 0.000589812242247841 -0.9999998258475306 0.0006158779205568468
                              children [
                                Shape {
                                  appearance USE LINKS_COLOR
                                  geometry DEF LINK_2_GM Box {
                                    size 0.05 0.05 0.15
                                  }
                                }
                                DEF LINK_3 Transform {
                                  translation 0 0 0.075
                                  children [
                                    Solid {
                                      translation 0.15070900000000004 0 0
                                      rotation 0.003753299385670586 -0.9999831433038613 -0.004430107431061613 0.000433209885579818
                                      children [
                                        Shape {
                                          appearance USE LINKS_COLOR
                                          geometry DEF LINK_3_GM Box {
                                            size 0.3 0.1 0.05
                                          }
                                        }
                                        DEF LINK_4 Transform {
                                          translation 0.15 0 0
                                          children [
                                            HingeJoint {
                                              jointParameters HingeJointParameters {
                                                axis 0 0 1
                                              }
                                              device [
                                                PositionSensor {
                                                  name "position sensor link 3"
                                                }
                                                RotationalMotor {
                                                  name "rotational motor link 3"
                                                  maxTorque 50
                                                }
                                              ]
                                              endPoint Solid {
                                                translation 0.12499999999999968 0 -0.049999999999999656
                                                rotation 0 0 1 0
                                                children [
                                                  Shape {
                                                    appearance USE LINKS_COLOR
                                                    geometry DEF LINK_4_GM Box {
                                                      size 0.25 0.075 0.05
                                                    }
                                                  }
                                                  DEF LINK_5 Transform {
                                                    translation 0.125 0 0
                                                    children [
                                                      HingeJoint {
                                                        jointParameters HingeJointParameters {
                                                          axis 0 0 1
                                                        }
                                                        device [
                                                          RotationalMotor {
                                                            name "rotational motor link 4"
                                                          }
                                                          PositionSensor {
                                                            name "position sensor link 4"
                                                          }
                                                        ]
                                                        endPoint Solid {
                                                          translation 0.050000000000000044 1.7313353441877899e-18 -0.04999999999999989
                                                          rotation 0 0 1 0
                                                          children [
                                                            Shape {
                                                              appearance USE LINKS_COLOR
                                                              geometry DEF LINK_5_GM Box {
                                                                size 0.1 0.05 0.05
                                                              }
                                                            }
                                                            DEF JOINT5_TRANS Transform {
                                                              translation 0.075 0 0
                                                              rotation 1 0 0 -1.571
                                                              children [
                                                                Shape {
                                                                  appearance DEF DARK_JOIN PBRAppearance {
                                                                    baseColor 0.533333 0.541176 0.521569
                                                                    roughness 0.4
                                                                    metalness 0
                                                                  }
                                                                  geometry Cylinder {
                                                                    height 0.05
                                                                    radius 0.025
                                                                  }
                                                                }
                                                              ]
                                                            }
                                                            Solid {
                                                              translation 0.028 0 0
                                                              rotation 0 0 1 -1.57
                                                              scale 0.647074 0.647074 0.647074
                                                              children [
                                                                Group {
                                                                }
                                                                DEF WRIST_GROUP Group {
                                                                  children [
                                                                    Transform {
                                                                      translation 0 0.136 0
                                                                      children [
                                                                        Shape {
                                                                          appearance DEF DARK PBRAppearance {
                                                                            baseColor 0.301961 0.301961 0.301961
                                                                            roughness 0.3
                                                                            metalness 0
                                                                          }
                                                                          geometry Cylinder {
                                                                            height 0.05
                                                                            radius 0.019
                                                                          }
                                                                        }
                                                                      ]
                                                                    }
                                                                    Transform {
                                                                      translation 0 0.1845 0
                                                                      children [
                                                                        Shape {
                                                                          appearance USE DARK
                                                                          geometry Cylinder {
                                                                            height 0.047
                                                                            radius 0.026
                                                                          }
                                                                        }
                                                                      ]
                                                                    }
                                                                    Transform {
                                                                      translation 0 0.222 0
                                                                      children [
                                                                        Shape {
                                                                          appearance DEF WHITE PBRAppearance {
                                                                            roughness 0.4
                                                                            metalness 0
                                                                          }
                                                                          geometry Cylinder {
                                                                            height 0.03
                                                                            radius 0.015
                                                                          }
                                                                        }
                                                                      ]
                                                                    }
                                                                  ]
                                                                }
                                                                DEF GripperR SliderJoint {
                                                                  jointParameters JointParameters {
                                                                    axis -1 0 0
                                                                  }
                                                                  device [
                                                                    LinearMotor {
                                                                      name "joint_GripperR"
                                                                      minPosition -0.004
                                                                      maxPosition 0.01
                                                                    }
                                                                  ]
                                                                  endPoint Solid {
                                                                    translation -0.007 0.23 0
                                                                    rotation 0 1 0 -1.5708
                                                                    children [
                                                                      Transform {
                                                                        rotation 0 1 0 1.5708
                                                                        children [
                                                                          Shape {
                                                                            appearance USE DARK_JOIN
                                                                            geometry DEF GripperR_FACES IndexedFaceSet {
                                                                              coord DEF GripperR_COORD Coordinate {
                                                                                point [
                                                                                  -0.003226 0 0.01065
                                                                                  0.003226 0 0.01065
                                                                                  -0.003226 0 -0.01065
                                                                                  0.003226 0 -0.01065
                                                                                  -0.003226 0.03851 0.01065
                                                                                  0.003226 0.03851 0.01065
                                                                                  -0.003226 0.03851 -0.01065
                                                                                  0.003226 0.03851 -0.01065
                                                                                  -0.009777 0 0.06255
                                                                                  -0.003224 0 0.06255
                                                                                  -0.009777 0 -0.06255
                                                                                  -0.003224 0 -0.06255
                                                                                  -0.009777 0.03851 0.06255
                                                                                  -0.003224 0.03851 0.06255
                                                                                  -0.009777 0.03851 -0.06255
                                                                                  -0.003224 0.03851 -0.06255
                                                                                ]
                                                                              }
                                                                              texCoord DEF GripperR_TEXCOORD TextureCoordinate {
                                                                                point [
                                                                                  0 0
                                                                                  1 0
                                                                                  0 1
                                                                                  1 1
                                                                                  0 0
                                                                                  1 0
                                                                                  0 1
                                                                                  1 1
                                                                                  0 0
                                                                                  1 0
                                                                                  0 1
                                                                                  1 1
                                                                                  0 0
                                                                                  1 0
                                                                                  0 1
                                                                                  1 1
                                                                                  0 0
                                                                                  1 0
                                                                                  0 1
                                                                                  1 1
                                                                                  0 0
                                                                                  1 0
                                                                                  0 1
                                                                                  1 1
                                                                                ]
                                                                              }
                                                                              coordIndex [
                                                                                0, 2, 3, -1, 3, 1, 0, -1, 4, 5, 7, -1, 7, 6, 4, -1, 0, 1, 5, -1, 5, 4, 0, -1, 1, 3, 7, -1, 7, 5, 1, -1, 3, 2, 6, -1, 6, 7, 3, -1, 2, 0, 4, -1, 4, 6, 2, -1
                                                                              ]
                                                                            }
                                                                          }
                                                                          Shape {
                                                                            appearance DEF CREAM PBRAppearance {
                                                                              baseColor 0.8314 0.8078 0.7451
                                                                              roughness 0.4
                                                                              metalness 0
                                                                            }
                                                                          }
                                                                        ]
                                                                      }
                                                                    ]
                                                                    name "GripperR"
                                                                    boundingObject DEF GRIP_BO Transform {
                                                                      translation 0 0.023 0
                                                                      children [
                                                                        Box {
                                                                          size 0.021 0.031 0.006
                                                                        }
                                                                      ]
                                                                    }
                                                                    physics Physics {
                                                                    }
                                                                  }
                                                                }
                                                                DEF GripperL SliderJoint {
                                                                  jointParameters JointParameters {
                                                                    axis 1 0 0
                                                                  }
                                                                  device [
                                                                    LinearMotor {
                                                                      name "joint_GripperL"
                                                                      minPosition -0.004
                                                                      maxPosition 0.01
                                                                    }
                                                                  ]
                                                                  endPoint Solid {
                                                                    translation 0.007 0.23 0
                                                                    rotation 0 1 0 1.5708
                                                                    children [
                                                                      DEF GripperL Transform {
                                                                        rotation 0 1 0 -1.5708
                                                                        children [
                                                                          Shape {
                                                                            appearance USE DARK_JOIN
                                                                            geometry DEF GripperL_FACES IndexedFaceSet {
                                                                              coord DEF GripperL_COORD Coordinate {
                                                                                point [
                                                                                  -0.003226 0 0.01065
                                                                                  0.003226 0 0.01065
                                                                                  -0.003226 0 -0.01065
                                                                                  0.003226 0 -0.01065
                                                                                  -0.003226 0.03851 0.01065
                                                                                  0.003226 0.03851 0.01065
                                                                                  -0.003226 0.03851 -0.01065
                                                                                  0.003226 0.03851 -0.01065
                                                                                  0.003224 0 0.06255
                                                                                  0.009777 0 0.06255
                                                                                  0.003224 0 -0.06255
                                                                                  0.009777 0 -0.06255
                                                                                  0.003224 0.03851 0.06255
                                                                                  0.009777 0.03851 0.06255
                                                                                  0.003224 0.03851 -0.06255
                                                                                  0.009777 0.03851 -0.06255
                                                                                ]
                                                                              }
                                                                              texCoord DEF GripperL_TEXCOORD TextureCoordinate {
                                                                                point [
                                                                                  0 0
                                                                                  1 0
                                                                                  0 1
                                                                                  1 1
                                                                                  0 0
                                                                                  1 0
                                                                                  0 1
                                                                                  1 1
                                                                                  0 0
                                                                                  1 0
                                                                                  0 1
                                                                                  1 1
                                                                                  0 0
                                                                                  1 0
                                                                                  0 1
                                                                                  1 1
                                                                                  0 0
                                                                                  1 0
                                                                                  0 1
                                                                                  1 1
                                                                                  0 0
                                                                                  1 0
                                                                                  0 1
                                                                                  1 1
                                                                                ]
                                                                              }
                                                                              coordIndex [
                                                                                0, 2, 3, -1, 3, 1, 0, -1, 4, 5, 7, -1, 7, 6, 4, -1, 0, 1, 5, -1, 5, 4, 0, -1, 1, 3, 7, -1, 7, 5, 1, -1, 3, 2, 6, -1, 6, 7, 3, -1, 2, 0, 4, -1, 4, 6, 2, -1
                                                                              ]
                                                                            }
                                                                          }
                                                                          Shape {
                                                                            appearance USE CREAM
                                                                          }
                                                                        ]
                                                                      }
                                                                    ]
                                                                    name "GripperL"
                                                                    boundingObject USE GRIP_BO
                                                                    physics Physics {
                                                                    }
                                                                  }
                                                                }
                                                              ]
                                                              boundingObject USE WRIST_GROUP
                                                              physics Physics {
                                                              }
                                                            }
                                                          ]
                                                          boundingObject USE LINK_5_GM
                                                          physics Physics {
                                                          }
                                                        }
                                                      }
                                                    ]
                                                  }
                                                ]
                                                boundingObject USE LINK_4_GM
                                                physics Physics {
                                                }
                                              }
                                            }
                                          ]
                                        }
                                      ]
                                      boundingObject USE LINK_3_GM
                                      physics Physics {
                                      }
                                    }
                                  ]
                                }
                              ]
                              boundingObject USE LINK_2_GM
                              physics Physics {
                              }
                            }
                          }
                        ]
                      }
                    ]
                    name "solid(1)"
                    boundingObject USE LINK_1_GM
                    physics Physics {
                    }
                  }
                }
              ]
            }
          ]
        }
      ]
    }
  ]
  physics Physics {
    mass 45
  }
  controller "RRT"
  battery [
    0
  ]
}
DEF WALL_1 Solid {
  translation -1 0.25 -0.7
  children [
    Shape {
      appearance DEF WALL_SH PBRAppearance {
        baseColor 0.729412 0.54902 0.388235
        roughness 1
        metalness 0
      }
      geometry Box {
        size 4 0.5 0.3
      }
    }
  ]
}
DEF WALL_2 Solid {
  translation 1 0.25 1.4
  children [
    Shape {
      appearance DEF WALL_SH PBRAppearance {
        baseColor 0.729412 0.54902 0.388235
        roughness 1
        metalness 0
      }
      geometry Box {
        size 4 0.5 0.3
      }
    }
  ]
  name "solid(1)"
}
YoubotFlag {
  translation 2 0 2.3
  rotation 0 1 0 0.78
}
