#VRML_SIM R2021b utf8
WorldInfo {
  coordinateSystem "NUE"
}
Viewpoint {
  orientation 1 0 0 4.71238898038469
  position 0.00010274583355837024 21.251652942043535 4.0691149853808505e-07
  follow "robot"
  followType "None"
}
TexturedBackground {
}
TexturedBackgroundLight {
}
RectangleArena {
  floorSize 6 6
}
Robot {
  translation -2.5 0.0333498 -2.5
  children [
    GPS {
    }
    Compass {
    }
    DEF GROUP_RB Group {
      children [
        DEF WHEELS_GR Group {
          children [
            DEF WHEEL_1 Transform {
              translation -0.115 0 -0.139
              rotation 0 1 0 0.6999996938995747
              children [
                HingeJoint {
                  jointParameters HingeJointParameters {
                    axis 0 0 1
                  }
                  device [
                    RotationalMotor {
                      name "wheel motor 1"
                      controlPID 10 0 5
                      maxVelocity 100
                      maxTorque 50
                    }
                    PositionSensor {
                      name "position_sensor1"
                      resolution 0.003848528
                    }
                  ]
                  endPoint Solid {
                    translation -2.1022674952721985e-05 -0.00010036692727753012 -4.741542575070755e-06
                    rotation -0.002111498507350384 -0.0006260111646812125 0.999997574839097 5.8956277927417435
                    children [
                      DEF WHEELS_TR1 Transform {
                        rotation 1 0 0 1.57
                        children [
                          DEF WHEELS_SH Shape {
                            appearance DEF COLOR_WHEEL PBRAppearance {
                              baseColor 0 0 0
                              roughness 1
                              metalness 0
                            }
                            geometry DEF SIZE_WHEEL Cylinder {
                              height 0.02
                              radius 0.04
                            }
                          }
                        ]
                      }
                      DEF SW1_1 HingeJoint {
                        jointParameters HingeJointParameters {
                          anchor 0 0.04 0
                        }
                        endPoint Solid {
                          translation 0 0.04 0
                          rotation -7.668291620332682e-09 7.662188124384302e-09 1 1.569999999999995
                          children [
                            DEF SMALL_WHEEL_TR1 Transform {
                              children [
                                DEF SMALL_WHEEL_SH Shape {
                                  appearance PBRAppearance {
                                    roughness 1
                                    metalness 0
                                  }
                                  geometry Cylinder {
                                    height 0.02
                                    radius 0.005
                                  }
                                }
                              ]
                            }
                          ]
                          boundingObject USE SMALL_WHEEL_TR1
                          physics Physics {
                            mass 0.1
                          }
                        }
                      }
                      DEF SW1_2 HingeJoint {
                        jointParameters HingeJointParameters {
                          axis 1 -1 0
                          anchor 0.02828 0.02828 0
                        }
                        endPoint Solid {
                          translation 0.02828 0.02828 0
                          rotation -3.260069184913756e-09 7.869410643747986e-09 1 0.7852999999999911
                          children [
                            USE SMALL_WHEEL_SH
                          ]
                          name "solid(1)"
                          boundingObject USE SMALL_WHEEL_SH
                          physics Physics {
                            mass 0.1
                          }
                        }
                      }
                      DEF SW1_3 HingeJoint {
                        jointParameters HingeJointParameters {
                          axis 1 1 0
                          anchor -0.02828 0.02828 0
                        }
                        endPoint Solid {
                          translation -0.02828 0.02828 0
                          rotation -7.573326429514778e-09 -1.8281093125959652e-08 -0.9999999999999998 0.7852999999999848
                          children [
                            Transform {
                              children [
                                USE SMALL_WHEEL_SH
                              ]
                            }
                          ]
                          name "solid(2)"
                          boundingObject USE SMALL_WHEEL_SH
                          physics Physics {
                            mass 0.1
                          }
                        }
                      }
                      DEF SW1_4 HingeJoint {
                        jointParameters HingeJointParameters {
                          axis 0 1 0
                          anchor -0.04 0 0
                        }
                        endPoint Solid {
                          translation -0.04 0 0
                          children [
                            Transform {
                              children [
                                USE SMALL_WHEEL_SH
                              ]
                            }
                          ]
                          name "solid(3)"
                          boundingObject USE SMALL_WHEEL_SH
                          physics Physics {
                            mass 0.1
                          }
                        }
                      }
                      DEF SW1_5 HingeJoint {
                        jointParameters HingeJointParameters {
                          axis 0 1 0
                          anchor 0.04 0 0
                        }
                        endPoint Solid {
                          translation 0.04 0 0
                          children [
                            Transform {
                              children [
                                USE SMALL_WHEEL_SH
                              ]
                            }
                          ]
                          name "solid(4)"
                          boundingObject USE SMALL_WHEEL_SH
                          physics Physics {
                            mass 0.1
                          }
                        }
                      }
                      DEF SW1_6 HingeJoint {
                        jointParameters HingeJointParameters {
                          axis 1 -1 0
                          anchor -0.02828 -0.02828 0
                        }
                        endPoint Solid {
                          translation -0.02828 -0.02828 0
                          rotation -3.260068749689311e-09 7.869411078972471e-09 1 0.7852999999999882
                          children [
                            Transform {
                              children [
                                USE SMALL_WHEEL_SH
                              ]
                            }
                          ]
                          name "solid(5)"
                          boundingObject USE SMALL_WHEEL_SH
                          physics Physics {
                            mass 0.1
                          }
                        }
                      }
                      DEF SW1_7 HingeJoint {
                        jointParameters HingeJointParameters {
                          axis 1 1 0
                          anchor 0.02828 -0.02828 0
                        }
                        endPoint Solid {
                          translation 0.02828 -0.02828 0
                          rotation 6.481271773944651e-10 1.5644987656015645e-09 -1 0.7852999999999819
                          children [
                            Transform {
                              children [
                                USE SMALL_WHEEL_SH
                              ]
                            }
                          ]
                          name "solid(6)"
                          boundingObject USE SMALL_WHEEL_SH
                          physics Physics {
                            mass 0.1
                          }
                        }
                      }
                      DEF SW1_8 HingeJoint {
                        jointParameters HingeJointParameters {
                          anchor 0 -0.04 0
                        }
                        endPoint Solid {
                          translation 0 -0.04 0
                          rotation 6.528325489522325e-10 -6.523101477842024e-10 1 1.5699999999999956
                          children [
                            Transform {
                              children [
                                USE SMALL_WHEEL_SH
                              ]
                            }
                          ]
                          name "solid(7)"
                          boundingObject USE SMALL_WHEEL_SH
                          physics Physics {
                            mass 0.1
                          }
                        }
                      }
                    ]
                    name "solid(4)"
                    boundingObject USE WHEELS_TR1
                    physics Physics {
                      mass 0.1
                    }
                  }
                }
              ]
            }
            DEF WHEEL_2 Transform {
              translation -0.115 0 0.139
              rotation 0 1 0 -0.7
              children [
                HingeJoint {
                  jointParameters HingeJointParameters {
                    axis 0 0 1
                  }
                  device [
                    RotationalMotor {
                      name "wheel motor 2"
                      controlPID 10 0 5
                      maxVelocity 100
                      maxTorque 50
                    }
                    PositionSensor {
                      name "position_sensor2"
                      resolution 0.003848528
                    }
                  ]
                  endPoint Solid {
                    translation 7.487471054116357e-05 -2.6036251455752277e-06 8.505712828676925e-06
                    rotation 0.0037795445435367526 -0.0036290150932076974 0.999986272552027 6.074605488200025
                    children [
                      DEF WHEEL_TR2 Transform {
                        rotation 1 0 0 1.57
                        children [
                          USE WHEELS_SH
                        ]
                      }
                      DEF SW2_1 HingeJoint {
                        jointParameters HingeJointParameters {
                          anchor 0 0.04 0
                        }
                        endPoint Solid {
                          translation 0 0.04 0
                          rotation 1.236858217974427e-08 -1.2358737390626031e-08 0.9999999999999999 1.569999999999995
                          children [
                            DEF SMALL_WHEEL_TR2 Transform {
                              children [
                                USE SMALL_WHEEL_SH
                              ]
                            }
                          ]
                          boundingObject USE SMALL_WHEEL_TR2
                          physics Physics {
                            mass 0.1
                          }
                        }
                      }
                      DEF SW2_2 HingeJoint {
                        jointParameters HingeJointParameters {
                          axis 1 -1 0
                          anchor 0.02828 0.02828 0
                        }
                        endPoint Solid {
                          translation 0.02828 0.02828 0
                          rotation -7.950253876952628e-10 1.9190926518479193e-09 1 0.7852999999999866
                          children [
                            Transform {
                              children [
                                USE SMALL_WHEEL_SH
                              ]
                            }
                          ]
                          name "solid(1)"
                          boundingObject USE SMALL_WHEEL_SH
                          physics Physics {
                          }
                        }
                      }
                      DEF SW2_3 HingeJoint {
                        jointParameters HingeJointParameters {
                          axis 1 1 0
                          anchor -0.02828 0.02828 0
                        }
                        endPoint Solid {
                          translation -0.02828 0.02828 0
                          rotation -5.927846265077624e-09 -1.4309099567833727e-08 -0.9999999999999999 0.785299999999979
                          children [
                            Transform {
                              children [
                                USE SMALL_WHEEL_SH
                              ]
                            }
                          ]
                          name "solid(2)"
                          boundingObject USE SMALL_WHEEL_SH
                          physics Physics {
                            mass 0.1
                          }
                        }
                      }
                      DEF SW2_4 HingeJoint {
                        jointParameters HingeJointParameters {
                          axis 0 1 0
                          anchor -0.04 0 0
                        }
                        endPoint Solid {
                          translation -0.04 0 0
                          children [
                            Transform {
                              children [
                                USE SMALL_WHEEL_SH
                              ]
                            }
                          ]
                          name "solid(3)"
                          boundingObject USE SMALL_WHEEL_SH
                          physics Physics {
                            mass 0.1
                          }
                        }
                      }
                      DEF SW2_5 HingeJoint {
                        jointParameters HingeJointParameters {
                          axis 0 1 0
                          anchor 0.04 0 0
                        }
                        endPoint Solid {
                          translation 0.04 0 0
                          rotation 0 1 0 1.5700000000006198
                          children [
                            Transform {
                              children [
                                USE SMALL_WHEEL_SH
                              ]
                            }
                          ]
                          name "solid(4)"
                          boundingObject USE SMALL_WHEEL_SH
                          physics Physics {
                            mass 0.1
                          }
                        }
                      }
                      DEF SW2_6 HingeJoint {
                        jointParameters HingeJointParameters {
                          axis 1 -1 0
                          anchor -0.02828 -0.02828 0
                        }
                        endPoint Solid {
                          translation -0.02828 -0.02828 0
                          rotation -7.950263306815866e-10 1.919092361698277e-09 1 0.7852999999999888
                          children [
                            Transform {
                              children [
                                USE SMALL_WHEEL_SH
                              ]
                            }
                          ]
                          name "solid(5)"
                          boundingObject USE SMALL_WHEEL_SH
                          physics Physics {
                            mass 0.1
                          }
                        }
                      }
                      DEF SW2_7 HingeJoint {
                        jointParameters HingeJointParameters {
                          axis 1 1 0
                          anchor 0.02828 -0.02828 0
                        }
                        endPoint Solid {
                          translation 0.02828 -0.02828 0
                          rotation -5.927844560448488e-09 -1.4309096865815198e-08 -0.9999999999999999 0.7852999999999801
                          children [
                            Transform {
                              children [
                                USE SMALL_WHEEL_SH
                              ]
                            }
                          ]
                          name "solid(6)"
                          boundingObject USE SMALL_WHEEL_SH
                          physics Physics {
                            mass 0.1
                          }
                        }
                      }
                      DEF SW2_8 HingeJoint {
                        jointParameters HingeJointParameters {
                          anchor 0 -0.04 0
                        }
                        endPoint Solid {
                          translation 0 -0.04 0
                          rotation -3.9267949639574944e-16 0 1 1.5699999999999974
                          children [
                            Transform {
                              children [
                                USE SMALL_WHEEL_SH
                              ]
                            }
                          ]
                          name "solid(7)"
                          boundingObject USE SMALL_WHEEL_SH
                          physics Physics {
                            mass 0.1
                          }
                        }
                      }
                    ]
                    name "solid(2)"
                    boundingObject USE WHEEL_TR2
                    physics Physics {
                      mass 0.1
                    }
                  }
                }
              ]
            }
            DEF WHEEL_3 Transform {
              translation 0.18 0 0
              rotation 0 1 0 1.57
              children [
                HingeJoint {
                  jointParameters HingeJointParameters {
                    axis 0 0 1
                  }
                  device [
                    RotationalMotor {
                      name "wheel motor 3"
                      controlPID 10 0 5
                      maxVelocity 100
                      maxTorque 50
                    }
                    PositionSensor {
                      name "position_sensor3"
                      resolution 0.003848528
                    }
                  ]
                  endPoint Solid {
                    translation -5.08010733144984e-05 0.00043303190987550476 1.170381764481472e-05
                    rotation -2.358792332729949e-07 6.091967498161333e-06 -0.9999999999814161 0.18654317754715652
                    children [
                      DEF WHEEL_TR3 Transform {
                        rotation 1 0 0 1.57
                        children [
                          USE WHEELS_SH
                        ]
                      }
                      DEF SW3_1 HingeJoint {
                        jointParameters HingeJointParameters {
                          anchor 0 0.04 0
                        }
                        endPoint Solid {
                          translation 0 0.04 0
                          rotation -4.1139059586310766e-09 4.110630697487539e-09 1 1.569999999999997
                          children [
                            Transform {
                              children [
                                USE SMALL_WHEEL_SH
                              ]
                            }
                          ]
                          boundingObject USE SMALL_WHEEL_SH
                          physics Physics {
                            mass 0.1
                          }
                        }
                      }
                      DEF SW3_2 HingeJoint {
                        jointParameters HingeJointParameters {
                          axis 1 -1 0
                          anchor 0.02828 0.02828 0
                        }
                        endPoint Solid {
                          translation 0.02828 0.02828 0
                          rotation -2.356686072741224e-09 5.688756108085881e-09 1 0.7852999999999796
                          children [
                            Transform {
                              children [
                                USE SMALL_WHEEL_SH
                              ]
                            }
                          ]
                          name "solid(1)"
                          boundingObject USE SMALL_WHEEL_SH
                          physics Physics {
                            mass 0.1
                          }
                        }
                      }
                      DEF SW3_3 HingeJoint {
                        jointParameters HingeJointParameters {
                          axis 1 1 0
                          anchor -0.02828 0.02828 0
                        }
                        endPoint Solid {
                          translation -0.02828 0.02828 0
                          rotation -3.4573364113548605e-09 -8.34559024903283e-09 -1 0.7852999999999918
                          children [
                            Transform {
                              children [
                                USE SMALL_WHEEL_SH
                              ]
                            }
                          ]
                          name "solid(2)"
                          boundingObject USE SMALL_WHEEL_SH
                          physics Physics {
                            mass 0.1
                          }
                        }
                      }
                      DEF SW3_4 HingeJoint {
                        jointParameters HingeJointParameters {
                          axis 0 1 0
                          anchor -0.04 0 0
                        }
                        endPoint Solid {
                          translation -0.04 0 0
                          children [
                            Transform {
                              children [
                                USE SMALL_WHEEL_SH
                              ]
                            }
                          ]
                          name "solid(3)"
                          boundingObject USE SMALL_WHEEL_SH
                          physics Physics {
                            mass 0.1
                          }
                        }
                      }
                      DEF SW3_5 HingeJoint {
                        jointParameters HingeJointParameters {
                          axis 0 1 0
                          anchor 0.04 0 0
                        }
                        endPoint Solid {
                          translation 0.04 0 0
                          rotation 0 1 0 1.5699999984434723
                          children [
                            Transform {
                              children [
                                USE SMALL_WHEEL_SH
                              ]
                            }
                          ]
                          name "solid(4)"
                          boundingObject USE SMALL_WHEEL_SH
                          physics Physics {
                            mass 0.1
                          }
                        }
                      }
                      DEF SW3_6 HingeJoint {
                        jointParameters HingeJointParameters {
                          axis 1 -1 0
                          anchor -0.02828 -0.02828 0
                        }
                        endPoint Solid {
                          translation -0.02828 -0.02828 0
                          rotation -2.3566889742375687e-09 5.68875821167066e-09 1 0.7852999999999947
                          children [
                            Transform {
                              children [
                                USE SMALL_WHEEL_SH
                              ]
                            }
                          ]
                          name "solid(5)"
                          boundingObject USE SMALL_WHEEL_SH
                          physics Physics {
                            mass 0.1
                          }
                        }
                      }
                      DEF SW3_7 HingeJoint {
                        jointParameters HingeJointParameters {
                          axis 1 1 0
                          anchor 0.02828 -0.02828 0
                        }
                        endPoint Solid {
                          translation 0.02828 -0.02828 0
                          rotation -3.4573357947868955e-09 -8.34558841746328e-09 -1 0.7852999999999877
                          children [
                            Transform {
                              children [
                                USE SMALL_WHEEL_SH
                              ]
                            }
                          ]
                          name "solid(6)"
                          boundingObject USE SMALL_WHEEL_SH
                          physics Physics {
                            mass 0.1
                          }
                        }
                      }
                      DEF SW3_8 HingeJoint {
                        jointParameters HingeJointParameters {
                          anchor 0 -0.04 0
                        }
                        endPoint Solid {
                          translation 0 -0.04 0
                          rotation 3.926794963957499e-17 3.926794963957499e-17 1 1.5699999999999952
                          children [
                            Transform {
                              children [
                                USE SMALL_WHEEL_SH
                              ]
                            }
                          ]
                          name "solid(7)"
                          boundingObject USE SMALL_WHEEL_SH
                          physics Physics {
                            mass 0.1
                          }
                        }
                      }
                    ]
                    name "solid(5)"
                    boundingObject USE WHEEL_TR3
                    physics Physics {
                      mass 0.1
                    }
                  }
                }
              ]
            }
          ]
        }
        DEF BASE_GR Group {
          children [
            DEF BOTTOM_BASE Transform {
              translation 0 0.015 0
              children [
                HingeJoint {
                  jointParameters HingeJointParameters {
                    axis 0 1 0
                  }
                  endPoint Solid {
                    translation -5.596120594664078e-18 0.14999999999999905 3.851859888774472e-34
                    children [
                      Shape {
                        appearance DEF BASE_COLOR PBRAppearance {
                          baseColor 0.180392 0.203922 0.211765
                          roughness 1
                          metalness 0
                        }
                        geometry DEF BOTTOM_BASE_GM Cylinder {
                          height 0.3
                          radius 0.17
                        }
                      }
                      DEF BASE_TOP Transform {
                        translation 0 0.175 0
                        children [
                          DEF solid Solid {
                            children [
                              Shape {
                                appearance USE BASE_COLOR
                                geometry DEF TOP_BASE Cylinder {
                                  height 0.05
                                  radius 0.1
                                }
                              }
                            ]
                            boundingObject USE TOP_BASE
                            physics Physics {
                            }
                          }
                        ]
                      }
                    ]
                    name "solid(3)"
                    boundingObject USE BOTTOM_BASE_GM
                    physics Physics {
                      mass 40
                    }
                  }
                }
              ]
            }
          ]
        }
        DEF LINKS_GR Group {
          children [
            DEF LINK_1 Transform {
              translation 0 0.525 0
              children [
                HingeJoint {
                  jointParameters HingeJointParameters {
                    axis 0 1 0
                  }
                  device [
                    RotationalMotor {
                      name "rotational motor link 1"
                      maxTorque 100
                    }
                    PositionSensor {
                      name "position sensor link 1"
                    }
                  ]
                  endPoint Solid {
                    translation 0 0.015999999999999827 0
                    rotation 9.026253910941507e-17 -2.8879622149060256e-05 0.9999999995829836 4.691192266720667e-06
                    children [
                      Shape {
                        appearance DEF LINKS_COLOR PBRAppearance {
                          baseColor 0 0 0
                          roughness 1
                          metalness 0
                        }
                        geometry DEF LINK_1_GM Cylinder {
                          height 0.35
                          radius 0.05
                        }
                      }
                      DEF LINK_2 Transform {
                        translation 0 0.175 0
                        children [
                          HingeJoint {
                            jointParameters HingeJointParameters {
                              axis 0 0 1
                            }
                            device [
                              RotationalMotor {
                                name "rotational motor link 2"
                                controlPID 50 5 0
                                maxTorque 300
                              }
                              PositionSensor {
                                name "position sensor link 2"
                              }
                            ]
                            endPoint Solid {
                              translation 3.995787345698733e-06 -1.106843118422876e-07 0.07500040380508283
                              rotation 2.0650122506818052e-05 0.0005898122422158524 -0.9999998258475306 0.0006158779205568468
                              children [
                                Shape {
                                  appearance USE LINKS_COLOR
                                  geometry DEF LINK_2_GM Box {
                                    size 0.05 0.05 0.15
                                  }
                                }
                                DEF LINK_3 Transform {
                                  translation 0 0 0.075
                                  children [
                                    Solid {
                                      translation 0.15070900000000004 0 0
                                      rotation 0.003753299385670586 -0.9999831433038613 -0.004430107431061613 0.000433209885579818
                                      children [
                                        Shape {
                                          appearance USE LINKS_COLOR
                                          geometry DEF LINK_3_GM Box {
                                            size 0.3 0.1 0.05
                                          }
                                        }
                                        DEF LINK_4 Transform {
                                          translation 0.15 0 0
                                          children [
                                            HingeJoint {
                                              jointParameters HingeJointParameters {
                                                axis 0 0 1
                                              }
                                              device [
                                                PositionSensor {
                                                  name "position sensor link 3"
                                                }
                                                RotationalMotor {
                                                  name "rotational motor link 3"
                                                  maxTorque 50
                                                }
                                              ]
                                              endPoint Solid {
                                                translation 0.1249999999999997 0 -0.04999999999999964
                                                rotation 0 0 1 0
                                                children [
                                                  Shape {
                                                    appearance USE LINKS_COLOR
                                                    geometry DEF LINK_4_GM Box {
                                                      size 0.25 0.075 0.05
                                                    }
                                                  }
                                                  DEF LINK_5 Transform {
                                                    translation 0.125 0 0
                                                    children [
                                                      HingeJoint {
                                                        jointParameters HingeJointParameters {
                                                          axis 0 0 1
                                                        }
                                                        device [
                                                          RotationalMotor {
                                                            name "rotational motor link 4"
                                                          }
                                                          PositionSensor {
                                                            name "position sensor link 4"
                                                          }
                                                        ]
                                                        endPoint Solid {
                                                          translation 0.05000000000000002 1.7313353441877899e-18 -0.049999999999999864
                                                          rotation 0 0 1 0
                                                          children [
                                                            Shape {
                                                              appearance USE LINKS_COLOR
                                                              geometry DEF LINK_5_GM Box {
                                                                size 0.1 0.05 0.05
                                                              }
                                                            }
                                                            DEF JOINT5_TRANS Transform {
                                                              translation 0.075 0 0
                                                              rotation 1 0 0 -1.571
                                                              children [
                                                                Shape {
                                                                  appearance DEF DARK_JOIN PBRAppearance {
                                                                    baseColor 0.533333 0.541176 0.521569
                                                                    roughness 0.4
                                                                    metalness 0
                                                                  }
                                                                  geometry Cylinder {
                                                                    height 0.05
                                                                    radius 0.025
                                                                  }
                                                                }
                                                              ]
                                                            }
                                                            Solid {
                                                              translation 0.028 0 0
                                                              rotation 0 0 1 -1.57
                                                              scale 0.647074 0.647074 0.647074
                                                              children [
                                                                Group {
                                                                }
                                                                DEF WRIST_GROUP Group {
                                                                  children [
                                                                    Transform {
                                                                      translation 0 0.136 0
                                                                      children [
                                                                        Shape {
                                                                          appearance DEF DARK PBRAppearance {
                                                                            baseColor 0.301961 0.301961 0.301961
                                                                            roughness 0.3
                                                                            metalness 0
                                                                          }
                                                                          geometry Cylinder {
                                                                            height 0.05
                                                                            radius 0.019
                                                                          }
                                                                        }
                                                                      ]
                                                                    }
                                                                    Transform {
                                                                      translation 0 0.1845 0
                                                                      children [
                                                                        Shape {
                                                                          appearance USE DARK
                                                                          geometry Cylinder {
                                                                            height 0.047
                                                                            radius 0.026
                                                                          }
                                                                        }
                                                                      ]
                                                                    }
                                                                    Transform {
                                                                      translation 0 0.222 0
                                                                      children [
                                                                        Shape {
                                                                          appearance DEF WHITE PBRAppearance {
                                                                            roughness 0.4
                                                                            metalness 0
                                                                          }
                                                                          geometry Cylinder {
                                                                            height 0.03
                                                                            radius 0.015
                                                                          }
                                                                        }
                                                                      ]
                                                                    }
                                                                  ]
                                                                }
                                                                DEF GripperR SliderJoint {
                                                                  jointParameters JointParameters {
                                                                    axis -1 0 0
                                                                  }
                                                                  device [
                                                                    LinearMotor {
                                                                      name "joint_GripperR"
                                                                      minPosition -0.004
                                                                      maxPosition 0.01
                                                                    }
                                                                  ]
                                                                  endPoint Solid {
                                                                    translation -0.007 0.23 0
                                                                    rotation 0 1 0 -1.5708
                                                                    children [
                                                                      Transform {
                                                                        rotation 0 1 0 1.5708
                                                                        children [
                                                                          Shape {
                                                                            appearance USE DARK_JOIN
                                                                            geometry DEF GripperR_FACES IndexedFaceSet {
                                                                              coord DEF GripperR_COORD Coordinate {
                                                                                point [
                                                                                  -0.003226 0 0.01065
                                                                                  0.003226 0 0.01065
                                                                                  -0.003226 0 -0.01065
                                                                                  0.003226 0 -0.01065
                                                                                  -0.003226 0.03851 0.01065
                                                                                  0.003226 0.03851 0.01065
                                                                                  -0.003226 0.03851 -0.01065
                                                                                  0.003226 0.03851 -0.01065
                                                                                  -0.009777 0 0.06255
                                                                                  -0.003224 0 0.06255
                                                                                  -0.009777 0 -0.06255
                                                                                  -0.003224 0 -0.06255
                                                                                  -0.009777 0.03851 0.06255
                                                                                  -0.003224 0.03851 0.06255
                                                                                  -0.009777 0.03851 -0.06255
                                                                                  -0.003224 0.03851 -0.06255
                                                                                ]
                                                                              }
                                                                              texCoord DEF GripperR_TEXCOORD TextureCoordinate {
                                                                                point [
                                                                                  0 0
                                                                                  1 0
                                                                                  0 1
                                                                                  1 1
                                                                                  0 0
                                                                                  1 0
                                                                                  0 1
                                                                                  1 1
                                                                                  0 0
                                                                                  1 0
                                                                                  0 1
                                                                                  1 1
                                                                                  0 0
                                                                                  1 0
                                                                                  0 1
                                                                                  1 1
                                                                                  0 0
                                                                                  1 0
                                                                                  0 1
                                                                                  1 1
                                                                                  0 0
                                                                                  1 0
                                                                                  0 1
                                                                                  1 1
                                                                                ]
                                                                              }
                                                                              coordIndex [
                                                                                0, 2, 3, -1, 3, 1, 0, -1, 4, 5, 7, -1, 7, 6, 4, -1, 0, 1, 5, -1, 5, 4, 0, -1, 1, 3, 7, -1, 7, 5, 1, -1, 3, 2, 6, -1, 6, 7, 3, -1, 2, 0, 4, -1, 4, 6, 2, -1
                                                                              ]
                                                                            }
                                                                          }
                                                                          Shape {
                                                                            appearance DEF CREAM PBRAppearance {
                                                                              baseColor 0.8314 0.8078 0.7451
                                                                              roughness 0.4
                                                                              metalness 0
                                                                            }
                                                                          }
                                                                        ]
                                                                      }
                                                                    ]
                                                                    name "GripperR"
                                                                    boundingObject DEF GRIP_BO Transform {
                                                                      translation 0 0.023 0
                                                                      children [
                                                                        Box {
                                                                          size 0.021 0.031 0.006
                                                                        }
                                                                      ]
                                                                    }
                                                                    physics Physics {
                                                                    }
                                                                  }
                                                                }
                                                                DEF GripperL SliderJoint {
                                                                  jointParameters JointParameters {
                                                                    axis 1 0 0
                                                                  }
                                                                  device [
                                                                    LinearMotor {
                                                                      name "joint_GripperL"
                                                                      minPosition -0.004
                                                                      maxPosition 0.01
                                                                    }
                                                                  ]
                                                                  endPoint Solid {
                                                                    translation 0.007 0.23 0
                                                                    rotation 0 1 0 1.5708
                                                                    children [
                                                                      DEF GripperL Transform {
                                                                        rotation 0 1 0 -1.5708
                                                                        children [
                                                                          Shape {
                                                                            appearance USE DARK_JOIN
                                                                            geometry DEF GripperL_FACES IndexedFaceSet {
                                                                              coord DEF GripperL_COORD Coordinate {
                                                                                point [
                                                                                  -0.003226 0 0.01065
                                                                                  0.003226 0 0.01065
                                                                                  -0.003226 0 -0.01065
                                                                                  0.003226 0 -0.01065
                                                                                  -0.003226 0.03851 0.01065
                                                                                  0.003226 0.03851 0.01065
                                                                                  -0.003226 0.03851 -0.01065
                                                                                  0.003226 0.03851 -0.01065
                                                                                  0.003224 0 0.06255
                                                                                  0.009777 0 0.06255
                                                                                  0.003224 0 -0.06255
                                                                                  0.009777 0 -0.06255
                                                                                  0.003224 0.03851 0.06255
                                                                                  0.009777 0.03851 0.06255
                                                                                  0.003224 0.03851 -0.06255
                                                                                  0.009777 0.03851 -0.06255
                                                                                ]
                                                                              }
                                                                              texCoord DEF GripperL_TEXCOORD TextureCoordinate {
                                                                                point [
                                                                                  0 0
                                                                                  1 0
                                                                                  0 1
                                                                                  1 1
                                                                                  0 0
                                                                                  1 0
                                                                                  0 1
                                                                                  1 1
                                                                                  0 0
                                                                                  1 0
                                                                                  0 1
                                                                                  1 1
                                                                                  0 0
                                                                                  1 0
                                                                                  0 1
                                                                                  1 1
                                                                                  0 0
                                                                                  1 0
                                                                                  0 1
                                                                                  1 1
                                                                                  0 0
                                                                                  1 0
                                                                                  0 1
                                                                                  1 1
                                                                                ]
                                                                              }
                                                                              coordIndex [
                                                                                0, 2, 3, -1, 3, 1, 0, -1, 4, 5, 7, -1, 7, 6, 4, -1, 0, 1, 5, -1, 5, 4, 0, -1, 1, 3, 7, -1, 7, 5, 1, -1, 3, 2, 6, -1, 6, 7, 3, -1, 2, 0, 4, -1, 4, 6, 2, -1
                                                                              ]
                                                                            }
                                                                          }
                                                                          Shape {
                                                                            appearance USE CREAM
                                                                          }
                                                                        ]
                                                                      }
                                                                    ]
                                                                    name "GripperL"
                                                                    boundingObject USE GRIP_BO
                                                                    physics Physics {
                                                                    }
                                                                  }
                                                                }
                                                              ]
                                                              boundingObject USE WRIST_GROUP
                                                              physics Physics {
                                                              }
                                                            }
                                                          ]
                                                          boundingObject USE LINK_5_GM
                                                          physics Physics {
                                                          }
                                                        }
                                                      }
                                                    ]
                                                  }
                                                ]
                                                boundingObject USE LINK_4_GM
                                                physics Physics {
                                                }
                                              }
                                            }
                                          ]
                                        }
                                      ]
                                      boundingObject USE LINK_3_GM
                                      physics Physics {
                                      }
                                    }
                                  ]
                                }
                              ]
                              boundingObject USE LINK_2_GM
                              physics Physics {
                              }
                            }
                          }
                        ]
                      }
                    ]
                    name "solid(1)"
                    boundingObject USE LINK_1_GM
                    physics Physics {
                    }
                  }
                }
              ]
            }
          ]
        }
      ]
    }
  ]
  physics Physics {
    mass 45
  }
  controller "RRT"
  battery [
    0
  ]
}
DEF WALL_1 Solid {
  translation 0 0.25 0
  children [
    Shape {
      appearance DEF WALL_SH PBRAppearance {
        baseColor 0.729412 0.54902 0.388235
        roughness 1
        metalness 0
      }
      geometry Box {
        size 2 0.5 2
      }
    }
  ]
}
DEF WALL_2 Solid {
  translation 0 0.25 1.5
  children [
    Shape {
      appearance DEF WALL_SH PBRAppearance {
        baseColor 0.729412 0.54902 0.388235
        roughness 1
        metalness 0
      }
      geometry Box {
        size 0.5 0.5 1
      }
    }
  ]
  name "solid(1)"
}
DEF WALL_3 Solid {
  translation 0 0.25 -1.5
  children [
    Shape {
      appearance DEF WALL_SH PBRAppearance {
        baseColor 0.729412 0.54902 0.388235
        roughness 1
        metalness 0
      }
      geometry Box {
        size 0.5 0.5 1
      }
    }
  ]
  name "solid(2)"
}
DEF WALL_4 Solid {
  translation -1.5 0.25 0
  rotation 0 1 0 1.57
  children [
    Shape {
      appearance DEF WALL_SH PBRAppearance {
        baseColor 0.729412 0.54902 0.388235
        roughness 1
        metalness 0
      }
      geometry Box {
        size 0.5 0.5 1
      }
    }
  ]
  name "solid(3)"
}
DEF WALL_5 Solid {
  translation 1.5 0.25 0
  rotation 0 1 0 1.57
  children [
    Shape {
      appearance DEF WALL_SH PBRAppearance {
        baseColor 0.729412 0.54902 0.388235
        roughness 1
        metalness 0
      }
      geometry Box {
        size 0.5 0.5 1
      }
    }
  ]
  name "solid(4)"
}
YoubotFlag {
  translation 2.3 0 2.3
}
